Eval split size: 0.01
Formatter name received: 'ljspeech'
 | > Found 21 files in C:\Users\trigg\Documents\GitHub\greg-ai\dataset
 > Using model: Tacotron2
 > Setting up Audio Processor...
 | > sample_rate:22050
 | > resample:False
 | > num_mels:80
 | > log_func:np.log10
 | > min_level_db:-100
 | > frame_shift_ms:None
 | > frame_length_ms:None
 | > ref_level_db:20
 | > fft_size:1024
 | > power:1.5
 | > preemphasis:0.0
 | > griffin_lim_iters:60
 | > signal_norm:True
 | > symmetric_norm:True
 | > mel_fmin:0
 | > mel_fmax:None
 | > pitch_fmin:1.0
 | > pitch_fmax:640.0
 | > spec_gain:20.0
 | > stft_pad_mode:reflect
 | > max_norm:4.0
 | > clip_norm:True
 | > do_trim_silence:True
 | > trim_db:45
 | > do_sound_norm:False
 | > do_amp_to_db_linear:True
 | > do_amp_to_db_mel:True
 | > do_rms_norm:False
 | > db_level:None
 | > stats_path:None
 | > base:10
 | > hop_length:256
 | > win_length:1024
 > Training Environment:
 | > Backend: Torch
 | > Mixed precision: False
 | > Precision: float32
 | > Current device: 0
 | > Num. of GPUs: 1
 | > Num. of CPUs: 12
 | > Num. of Torch Threads: 6
 | > Torch seed: 54321
 | > Torch CUDNN: True
 | > Torch CUDNN deterministic: False
 | > Torch CUDNN benchmark: False
 | > Torch TF32 MatMul: False
 > Start Tensorboard: tensorboard --logdir=output\run-December-23-2024_02+41AM-6a2cc3d

 > Model has 28274290 parameters

 > EPOCH: 0/1000
 --> output\run-December-23-2024_02+41AM-6a2cc3d


> DataLoader initialization
| > Tokenizer:
        | > add_blank: False
        | > use_eos_bos: False
        | > use_phonemes: False
| > Number of instances : 20
Traceback (most recent call last):
  File "C:\Users\trigg\Documents\GitHub\greg-ai\.venv\lib\site-packages\trainer\trainer.py", line 1833, in fit 
    self._fit()
  File "C:\Users\trigg\Documents\GitHub\greg-ai\.venv\lib\site-packages\trainer\trainer.py", line 1785, in _fit
    self.train_epoch()
  File "C:\Users\trigg\Documents\GitHub\greg-ai\.venv\lib\site-packages\trainer\trainer.py", line 1483, in train_epoch
    self.train_loader = self.get_train_dataloader(
  File "C:\Users\trigg\Documents\GitHub\greg-ai\.venv\lib\site-packages\trainer\trainer.py", line 949, in get_train_dataloader
    return self._get_loader(
  File "C:\Users\trigg\Documents\GitHub\greg-ai\.venv\lib\site-packages\trainer\trainer.py", line 909, in _get_loader
    loader = model.get_data_loader(
  File "C:\Users\trigg\Documents\GitHub\greg-ai\.venv\lib\site-packages\TTS\tts\models\base_tts.py", line 346, in get_data_loader
    dataset.preprocess_samples()
  File "C:\Users\trigg\Documents\GitHub\greg-ai\.venv\lib\site-packages\TTS\tts\datasets\dataset.py", line 346, in preprocess_samples
    samples = self._compute_lengths(self.samples)
  File "C:\Users\trigg\Documents\GitHub\greg-ai\.venv\lib\site-packages\TTS\tts\datasets\dataset.py", line 298, in _compute_lengths
    audio_length = os.path.getsize(item["audio_file"]) / 16 * 8  # assuming 16bit audio
  File "C:\Users\trigg\.pyenv\pyenv-win\versions\3.10.9\lib\genericpath.py", line 50, in getsize
    return os.stat(filename).st_size
FileNotFoundError: [WinError 2] The system cannot find the file specified: 'dataset/wavs\\audio_014.wav.wav'   

During handling of the above exception, another exception occurred:

Traceback (most recent call last):
  File "C:\Users\trigg\.pyenv\pyenv-win\versions\3.10.9\lib\runpy.py", line 196, in _run_module_as_main        
    return _run_code(code, main_globals, None,
  File "C:\Users\trigg\.pyenv\pyenv-win\versions\3.10.9\lib\runpy.py", line 86, in _run_code
    exec(code, run_globals)
  File "C:\Users\trigg\Documents\GitHub\greg-ai\.venv\lib\site-packages\TTS\bin\train_tts.py", line 86, in <module>
    main()
  File "C:\Users\trigg\Documents\GitHub\greg-ai\.venv\lib\site-packages\TTS\bin\train_tts.py", line 82, in main
    trainer.fit()
  File "C:\Users\trigg\Documents\GitHub\greg-ai\.venv\lib\site-packages\trainer\trainer.py", line 1860, in fit 
    remove_experiment_folder(self.output_path)
  File "C:\Users\trigg\Documents\GitHub\greg-ai\.venv\lib\site-packages\trainer\generic_utils.py", line 77, in remove_experiment_folder
    fs.rm(experiment_path, recursive=True)
  File "C:\Users\trigg\Documents\GitHub\greg-ai\.venv\lib\site-packages\fsspec\implementations\local.py", line 183, in rm
    shutil.rmtree(p)
  File "C:\Users\trigg\.pyenv\pyenv-win\versions\3.10.9\lib\shutil.py", line 750, in rmtree
    return _rmtree_unsafe(path, onerror)
  File "C:\Users\trigg\.pyenv\pyenv-win\versions\3.10.9\lib\shutil.py", line 620, in _rmtree_unsafe
    onerror(os.unlink, fullname, sys.exc_info())
  File "C:\Users\trigg\.pyenv\pyenv-win\versions\3.10.9\lib\shutil.py", line 618, in _rmtree_unsafe
    os.unlink(fullname)
PermissionError: [WinError 32] The process cannot access the file because it is being used by another process: 'C:/Users/trigg/Documents/GitHub/greg-ai/output/run-December-23-2024_02+41AM-6a2cc3d\\trainer_0_log.txt'       
(.venv) PS C:\Users\trigg\Documents\GitHub\greg-ai> 
(.venv) PS C:\Users\trigg\Documents\GitHub\greg-ai> 